Workbook

Sheet meteorologia
A1: IdProvincia | B1: IdEstacion | C1: Fecha | D1: Año | E1: Dia | F1: Temp Media (ºC) | G1: Humedad Media (%)
A2: 46 | B2: 29 | C2: 42736 | D2: 2017 | E2: 1 | F2: 7.25 | G2: 84.3
A3: 46 | B3: 29 | C3: 42737 | D3: 2017 | E3: 2 | F3: 6.41 | G3: 85.6
A4: 46 | B4: 29 | C4: 42738 | D4: 2017 | E4: 3 | F4: 10.09 | G4: 66.23
A5: 46 | B5: 29 | C5: 42739 | D5: 2017 | E5: 4 | F5: 12.11 | G5: 68.46
A6: 46 | B6: 29 | C6: 42740 | D6: 2017 | E6: 5 | F6: 9.74 | G6: 70.4
A7: 46 | B7: 29 | C7: 42741 | D7: 2017 | E7: 6 | F7: 7.11 | G7: 89.2
A8: 46 | B8: 29 | C8: 42742 | D8: 2017 | E8: 7 | F8: 6.7 | G8: 88
A9: 46 | B9: 29 | C9: 42743 | D9: 2017 | E9: 8 | F9: 5.9 | G9: 83.1
A10: 46 | B10: 29 | C10: 42744 | D10: 2017 | E10: 9 | F10: 6.46 | G10: 75.5
A11: 46 | B11: 29 | C11: 42745 | D11: 2017 | E11: 10 | F11: 9.56 | G11: 63.31
A12: 46 | B12: 29 | C12: 42746 | D12: 2017 | E12: 11 | F12: 10.53 | G12: 65.48
A13: 46 | B13: 29 | C13: 42747 | D13: 2017 | E13: 12 | F13: 13.23 | G13: 65.06
... A426: 46 | B426: 29 | C426: 43160 | D426: 2018 | E426: 60 | F426: 12.45 | G426: 73.4
A427: 46 | B427: 29 | C427: 43161 | D427: 2018 | E427: 61 | F427: 12.99
A428: 46 | B428: 29 | C428: 43162 | D428: 2018 | E428: 62 | F428: 14.91 | G428: 54.3
A429: 46 | B429: 29 | C429: 43163 | D429: 2018 | E429: 63 | F429: 13.11 | G429: 60.84
A430: 46 | B430: 29 | C430: 43164 | D430: 2018 | E430: 64 | F430: 11.87 | G430: 59.1
A431: 46 | B431: 29 | C431: 43165 | D431: 2018 | E431: 65 | F431: 12.48 | G431: 52.04
A432: 46 | B432: 29 | C432: 43166 | D432: 2018 | E432: 66 | F432: 11.9 | G432: 44.64
A433: 46 | B433: 29 | C433: 43167 | D433: 2018 | E433: 67 | F433: 12.79 | G433: 70.4
A434: 46 | B434: 29 | C434: 43168 | D434: 2018 | E434: 68 | F434: 17.62 | G434: 57.69
A435: 46 | B435: 29 | C435: 43169 | D435: 2018 | E435: 69 | F435: 16.65 | G435: 61.64
A436: 46 | B436: 29 | C436: 43170 | D436: 2018 | E436: 70 | F436: 13.38 | G436: 49.73
A437: 46 | B437: 29 | C437: 43171 | D437: 2018 | E437: 71 | F437: 13.53 | G437: 45.4
A438: 46 | B438: 29 | C438: 43172 | D438: 2018 | E438: 72 | F438: 14.76 | G438: 56.77
A439: 46 | B439: 29 | C439: 43173 | D439: 2018 | E439: 73 | F439: 16.63 | G439: 53.14
... A685: 46 | B685: 29 | C685: 43419 | D685: 2018 | E685: 319 | F685: 14.03 | G685: 99.9
A686: 46 | B686: 29 | C686: 43420 | D686: 2018 | E686: 320 | F686: 14.32
A687: 46 | B687: 29 | C687: 43421 | D687: 2018 | E687: 321 | F687: 13.66 | G687: 100
A688: 46 | B688: 29 | C688: 43422 | D688: 2018 | E688: 322 | F688: 12.73 | G688: 95.2
A689: 46 | B689: 29 | C689: 43423 | D689: 2018 | E689: 323 | F689: 11.4 | G689: 100
A690: 46 | B690: 29 | C690: 43424 | D690: 2018 | E690: 324 | F690: 13.57 | G690: 73.9
A691: 46 | B691: 29 | C691: 43425 | D691: 2018 | E691: 325 | F691: 12.54 | G691: 74.2
A692: 46 | B692: 29 | C692: 43426 | D692: 2018 | E692: 326 | F692: 11.27 | G692: 92.3
A693: 46 | B693: 29 | C693: 43427 | D693: 2018 | E693: 327 | F693: 11.19 | G693: 88.1
A694: 46 | B694: 29 | C694: 43428 | D694: 2018 | E694: 328 | F694: 9.72 | G694: 73.6
A695: 46 | B695: 29 | C695: 43429 | D695: 2018 | E695: 329 | F695: 14.76 | G695: 62.37
A696: 46 | B696: 29 | C696: 43430 | D696: 2018 | E696: 330 | F696: 13.62 | G696: 57.64
A697: 46 | B697: 29 | C697: 43431 | D697: 2018 | E697: 331 | F697: 12.58 | G697: 54.44
...

Sheet valencia
A1: FECHA | B1: PM25 | C1: PM10 | D1: SO2 | E1: O3 | F1: NO | G1: NO2 | H1: C6H6 | I1: NOx | J1: CO | K1: temperatura | L1: humedad | M1: ingresos | N1: exitus
A2: 42736 | B2: 13.473485 | C2: 14.833333 | D2: 3.1300198 | E2: 37.900721 | F2: 4.5858523 | G2: 15.776534 | H2: 2.15 | I2: 22.060227 | J2: 0.19070513 | K2: =AVERAGEIFS(meteorologia!F:F,meteorologia!C:C,valencia!A2) -> 6.3542857 | L2: =AVERAGEIFS(meteorologia!G:G,meteorologia!C:C,valencia!A2) -> 84.471429 | M2: =LOOKUP(valencia!A:A,Hoja4!A:A,Hoja4!B:B) -> 3 | N2: =LOOKUP(valencia!A:A,Hoja4!A:A,Hoja4!C:C) -> 1
A3: 42737 | B3: 15.405303 | C3: 17.397727 | D3: 3.202996 | E3: 27.921897 | F3: 19.76259 | G3: 27.030059 | H3: 2.9583333 | I3: 56.767751 | J3: 0.22837995 | K3: =AVERAGEIFS(meteorologia!F:F,meteorologia!C:C,valencia!A3) -> 5.2985714 | L3: =AVERAGEIFS(meteorologia!G:G,meteorologia!C:C,valencia!A3) -> 85.7 | M3: =LOOKUP(valencia!A:A,Hoja4!A:A,Hoja4!B:B) -> 2 | N3: =LOOKUP(valencia!A:A,Hoja4!A:A,Hoja4!C:C) -> 0
A4: 42738 | B4: 18.462121 | C4: 22.351614 | D4: 3.4767892 | E4: 24.743305 | F4: 31.644688 | G4: 29.78434 | H4: 4.175 | I4: 77.597357 | J4: 0.22388517 | K4: =AVERAGEIFS(meteorologia!F:F,meteorologia!C:C,valencia!A4) -> 8.2814286 | L4: =AVERAGEIFS(meteorologia!G:G,meteorologia!C:C,valencia!A4) -> 76.512857 | M4: =LOOKUP(valencia!A:A,Hoja4!A:A,Hoja4!B:B) -> 2 | N4: =LOOKUP(valencia!A:A,Hoja4!A:A,Hoja4!C:C) -> 0
A5: 42739 | B5: 16.437937 | C5: 20.663753 | D5: 3.3360667 | E5: 30.060205 | F5: 24.478559 | G5: 28.65891 | H5: 3.425 | I5: 65.497163 | J5: 0.17565896 | K5: =AVERAGEIFS(meteorologia!F:F,meteorologia!C:C,valencia!A5) -> 10.545714 | L5: =AVERAGEIFS(meteorologia!G:G,meteorologia!C:C,valencia!A5) -> 74.912857 | M5: =LOOKUP(valencia!A:A,Hoja4!A:A,Hoja4!B:B) -> 2 | N5: =LOOKUP(valencia!A:A,Hoja4!A:A,Hoja4!C:C) -> 0
A6: 42740 | B6: 8.6950758 | C6: 11.482955 | D6: 3.3697691 | E6: 35.841477 | F6: 14.18906 | G6: 25.653962 | H6: 2.8541667 | I6: 46.693406 | J6: 0.16698718 | K6: =AVERAGEIFS(meteorologia!F:F,meteorologia!C:C,valencia!A6) -> 9.0728571 | L6: =AVERAGEIFS(meteorologia!G:G,meteorologia!C:C,valencia!A6) -> 73.567143 | M6: =LOOKUP(valencia!A:A,Hoja4!A:A,Hoja4!B:B) -> 2 | N6: =LOOKUP(valencia!A:A,Hoja4!A:A,Hoja4!C:C) -> 0
A7: 42741 | B7: 10.912879 | C7: 12.719697 | D7: 2.987123 | E7: 36.827628 | F7: 7.3907197 | G7: 18.991288 | H7: 2.1791667 | I7: 30.004545 | J7: 0.17884615 | K7: =AVERAGEIFS(meteorologia!F:F,meteorologia!C:C,valencia!A7) -> 7.0557143 | L7: =AVERAGEIFS(meteorologia!G:G,meteorologia!C:C,valencia!A7) -> 86.471429 | M7: =LOOKUP(valencia!A:A,Hoja4!A:A,Hoja4!B:B) -> 2 | N7: =LOOKUP(valencia!A:A,Hoja4!A:A,Hoja4!C:C) -> 0
A8: 42742 | B8: 13.818182 | C8: 15.954545 | D8: 2.9921627 | E8: 31.778542 | F8: 11.43642 | G8: 20.60803 | H8: 2.9041667 | I8: 37.504924 | J8: 0.17532051 | K8: =AVERAGEIFS(meteorologia!F:F,meteorologia!C:C,valencia!A8) -> 6.1328571 | L8: =AVERAGEIFS(meteorologia!G:G,meteorologia!C:C,valencia!A8) -> 87.685714 | M8: =LOOKUP(valencia!A:A,Hoja4!A:A,Hoja4!B:B) -> 2 | N8: =LOOKUP(valencia!A:A,Hoja4!A:A,Hoja4!C:C) -> 0
A9: 42743 | B9: 14.587121 | C9: 16.75 | D9: 3.0837103 | E9: 30.025609 | F9: 10.581117 | G9: 19.383333 | H9: 2.55 | I9: 34.956061 | J9: 0.24326923 | K9: =AVERAGEIFS(meteorologia!F:F,meteorologia!C:C,valencia!A9) -> 5.5014286 | L9: =AVERAGEIFS(meteorologia!G:G,meteorologia!C:C,valencia!A9) -> 82.742857 | M9: =LOOKUP(valencia!A:A,Hoja4!A:A,Hoja4!B:B) -> 2 | N9: =LOOKUP(valencia!A:A,Hoja4!A:A,Hoja4!C:C) -> 0
A10: 42744 | B10: 14.627331 | C10: 18.488345 | D10: 3.2384325 | E10: 31.333038 | F10: 17.971941 | G10: 28.931237 | H10: 3.1833333 | I10: 55.983289 | J10: 0.18942308 | K10: =AVERAGEIFS(meteorologia!F:F,meteorologia!C:C,valencia!A10) -> 5.8171429 | L10: =AVERAGEIFS(meteorologia!G:G,meteorologia!C:C,valencia!A10) -> 79.042857 | M10: =LOOKUP(valencia!A:A,Hoja4!A:A,Hoja4!B:B) -> 2 | N10: =LOOKUP(valencia!A:A,Hoja4!A:A,Hoja4!C:C) -> 0
A11: 42745 | B11: 6.6215278 | C11: 10.381944 | D11: 2.9939773 | E11: 43.329075 | F11: 9.545082 | G11: 17.996509 | H11: 2.0791667 | I11: 31.702376 | J11: 0.1389881 | K11: =AVERAGEIFS(meteorologia!F:F,meteorologia!C:C,valencia!A11) -> 9.0757143 | L11: =AVERAGEIFS(meteorologia!G:G,meteorologia!C:C,valencia!A11) -> 67.46 | M11: =LOOKUP(valencia!A:A,Hoja4!A:A,Hoja4!B:B) -> 2 | N11: =LOOKUP(valencia!A:A,Hoja4!A:A,Hoja4!C:C) -> 0
A12: 42746 | B12: 4.5867918 | C12: 8.4944005 | D12: 3.2739087 | E12: 47.039803 | F12: 15.515229 | G12: 24.630789 | H12: 2.5458333 | I12: 47.816794 | J12: 0.15214326 | K12: =AVERAGEIFS(meteorologia!F:F,meteorologia!C:C,valencia!A12) -> 9.86 | L12: =AVERAGEIFS(meteorologia!G:G,meteorologia!C:C,valencia!A12) -> 69.432857 | M12: =LOOKUP(valencia!A:A,Hoja4!A:A,Hoja4!B:B) -> 2 | N12: =LOOKUP(valencia!A:A,Hoja4!A:A,Hoja4!C:C) -> 0
A13: 42747 | B13: 5.6704545 | C13: 9.6363636 | D13: 3.2419048 | E13: 31.280233 | F13: 16.829316 | G13: 20.046974 | H13: 2.6958333 | I13: 44.66373 | J13: 0.16493056 | K13: =AVERAGEIFS(meteorologia!F:F,meteorologia!C:C,valencia!A13) -> 11.767143 | L13: =AVERAGEIFS(meteorologia!G:G,meteorologia!C:C,valencia!A13) -> 71.15 | M13: =LOOKUP(valencia!A:A,Hoja4!A:A,Hoja4!B:B) -> 2 | N13: =LOOKUP(valencia!A:A,Hoja4!A:A,Hoja4!C:C) -> 0
... A378: 43477 | B378: 12.121212 | C378: 18.994132 | D378: 3.674881 | E378: 41.11474 | F378: 12.545578 | G378: 30.481476 | H378: 1.8 | I378: 49.165786 | J378: 0.21208965 | K378: =AVERAGEIFS(meteorologia!F:F,meteorologia!C:C,valencia!A378) -> 4.57375 | L378: =AVERAGEIFS(meteorologia!G:G,meteorologia!C:C,valencia!A378) -> 61.68 | M378: =LOOKUP(valencia!A:A,Hoja4!A:A,Hoja4!B:B) -> 2 | N378: =LOOKUP(valencia!A:A,Hoja4!A:A,Hoja4!C:C) -> 0
A379: 43478 | B379: 9.6325758 | C379: 14.183125 | D379: 3.749623 | E379: 38.314757 | F379: 10.322652 | G379: 24.351436 | I379: 39.635072 | J379: 0.19666667 | K379: =AVERAGEIFS(meteorologia!F:F,meteorologia!C:C,valencia!A379) -> 5.9875 | L379: =AVERAGEIFS(meteorologia!G:G,meteorologia!C:C,valencia!A379) -> 66.07 | M379: =LOOKUP(valencia!A:A,Hoja4!A:A,Hoja4!B:B) -> 2 | N379: =LOOKUP(valencia!A:A,Hoja4!A:A,Hoja4!C:C) -> 0
A380: 43479 | B380: 9.5151515 | C380: 18.433021 | D380: 4.1786111 | E380: 33.698074 | F380: 23.490974 | G380: 32.656137 | I380: 67.198835 | J380: 0.16208333 | K380: =AVERAGEIFS(meteorologia!F:F,meteorologia!C:C,valencia!A380) -> 8.88875 | L380: =AVERAGEIFS(meteorologia!G:G,meteorologia!C:C,valencia!A380) -> 66.66375 | M380: =LOOKUP(valencia!A:A,Hoja4!A:A,Hoja4!B:B) -> 2 | N380: =LOOKUP(valencia!A:A,Hoja4!A:A,Hoja4!C:C) -> 0
A381: 43480 | B381: 13.606061 | C381: 21.569167 | D381: 4.5559921 | E381: 29.8085 | F381: 26.964022 | G381: 34.509306 | I381: 75.247276 | J381: 0.16833333 | K381: =AVERAGEIFS(meteorologia!F:F,meteorologia!C:C,valencia!A381) -> 7.25875 | L381: =AVERAGEIFS(meteorologia!G:G,meteorologia!C:C,valencia!A381) -> 79.25875 | M381: =LOOKUP(valencia!A:A,Hoja4!A:A,Hoja4!B:B) -> 2 | N381: =LOOKUP(valencia!A:A,Hoja4!A:A,Hoja4!C:C) -> 0
A382: 43481 | B382: 25.704545 | C382: 32.72434 | D382: 4.069127 | E382: 28.260735 | F382: 25.815706 | G382: 35.384566 | I382: 74.553581 | J382: 0.16083333 | K382: =AVERAGEIFS(meteorologia!F:F,meteorologia!C:C,valencia!A382) -> 7.1925 | L382: =AVERAGEIFS(meteorologia!G:G,meteorologia!C:C,valencia!A382) -> 78.75 | M382: =LOOKUP(valencia!A:A,Hoja4!A:A,Hoja4!B:B) -> 2 | N382: =LOOKUP(valencia!A:A,Hoja4!A:A,Hoja4!C:C) -> 0
A383: 43482 | B383: 30.147727 | C383: 41.249896 | D383: 4.092054 | E383: 26.202874 | F383: 33.186674 | G383: 35.84994 | I383: 85.963406 | J383: 0.14951087 | K383: =AVERAGEIFS(meteorologia!F:F,meteorologia!C:C,valencia!A383) -> 7.095 | L383: =AVERAGEIFS(meteorologia!G:G,meteorologia!C:C,valencia!A383) -> 77.2225 | M383: =LOOKUP(valencia!A:A,Hoja4!A:A,Hoja4!B:B) -> 2 | N383: =LOOKUP(valencia!A:A,Hoja4!A:A,Hoja4!C:C) -> 0
A384: 43483 | B384: 10.349838 | C384: 17.87036 | D384: 3.4143505 | E384: 36.578534 | F384: 15.38054 | G384: 30.187493 | I384: 53.427037 | J384: 0.14648359 | K384: =AVERAGEIFS(meteorologia!F:F,meteorologia!C:C,valencia!A384) -> 6.81375 | L384: =AVERAGEIFS(meteorologia!G:G,meteorologia!C:C,valencia!A384) -> 66.725 | M384: =LOOKUP(valencia!A:A,Hoja4!A:A,Hoja4!B:B) -> 2 | N384: =LOOKUP(valencia!A:A,Hoja4!A:A,Hoja4!C:C) -> 0
A385: 43484 | B385: 11.886364 | C385: 15.850486 | D385: 3.2217083 | E385: 47.539146 | F385: 4.973687 | G385: 19.539267 | I385: 26.867417 | J385: 0.14409722 | K385: =AVERAGEIFS(meteorologia!F:F,meteorologia!C:C,valencia!A385) -> 8.09 | L385: =AVERAGEIFS(meteorologia!G:G,meteorologia!C:C,valencia!A385) -> 61.53125 | M385: =LOOKUP(valencia!A:A,Hoja4!A:A,Hoja4!B:B) -> 2 | N385: =LOOKUP(valencia!A:A,Hoja4!A:A,Hoja4!C:C) -> 0
A386: 43485 | B386: 8.5378788 | C386: 9.994809 | D386: 3.3235307 | E386: 39.8737 | F386: 6.259798 | G386: 18.86051 | I386: 28.204437 | J386: 0.15243056 | K386: =AVERAGEIFS(meteorologia!F:F,meteorologia!C:C,valencia!A386) -> 8.85625 | L386: =AVERAGEIFS(meteorologia!G:G,meteorologia!C:C,valencia!A386) -> 77.51875 | M386: =LOOKUP(valencia!A:A,Hoja4!A:A,Hoja4!B:B) -> 2 | N386: =LOOKUP(valencia!A:A,Hoja4!A:A,Hoja4!C:C) -> 0
A387: 43486 | B387: 3.8371212 | C387: 8.4031944 | D387: 3.6168668 | E387: 52.309221 | F387: 10.024483 | G387: 19.481937 | I387: 34.516146 | J387: 0.15324074 | K387: =AVERAGEIFS(meteorologia!F:F,meteorologia!C:C,valencia!A387) -> 7.44125 | L387: =AVERAGEIFS(meteorologia!G:G,meteorologia!C:C,valencia!A387) -> 58.66625 | M387: =LOOKUP(valencia!A:A,Hoja4!A:A,Hoja4!B:B) -> 2 | N387: =LOOKUP(valencia!A:A,Hoja4!A:A,Hoja4!C:C) -> 0
A388: 43487 | B388: 5.5227273 | C388: 10.803854 | D388: 3.2017105 | E388: 53.339275 | F388: 5.0490159 | G388: 15.0153 | I388: 22.407402 | J388: 0.16401515 | K388: =AVERAGEIFS(meteorologia!F:F,meteorologia!C:C,valencia!A388) -> 7.58625 | L388: =AVERAGEIFS(meteorologia!G:G,meteorologia!C:C,valencia!A388) -> 54.13875 | M388: =LOOKUP(valencia!A:A,Hoja4!A:A,Hoja4!B:B) -> 2 | N388: =LOOKUP(valencia!A:A,Hoja4!A:A,Hoja4!C:C) -> 0
A389: 43488 | B389: 4.063447 | C389: 16.972762 | D389: 3.1275833 | E389: 60.467863 | F389: 4.1158693 | G389: 10.468311 | I389: 16.322987 | J389: 0.14423077 | K389: =AVERAGEIFS(meteorologia!F:F,meteorologia!C:C,valencia!A389) -> 12.785 | L389: =AVERAGEIFS(meteorologia!G:G,meteorologia!C:C,valencia!A389) -> 52.62 | M389: =LOOKUP(valencia!A:A,Hoja4!A:A,Hoja4!B:B) -> 2 | N389: =LOOKUP(valencia!A:A,Hoja4!A:A,Hoja4!C:C) -> 0
A390: 43489 | B390: 2.6354167 | C390: 10.916615 | D390: 3.2465677 | E390: 67.000094 | F390: 3.9712318 | G390: 10.534497 | I390: 16.026642 | J390: 0.15737179 | K390: =AVERAGEIFS(meteorologia!F:F,meteorologia!C:C,valencia!A390) -> 11.68125 | L390: =AVERAGEIFS(meteorologia!G:G,meteorologia!C:C,valencia!A390) -> 50.92375 | M390: =LOOKUP(valencia!A:A,Hoja4!A:A,Hoja4!B:B) -> 1 | N390: =LOOKUP(valencia!A:A,Hoja4!A:A,Hoja4!C:C) -> 1
... A402: 43501 | B402: 9.7788462 | C402: 18.419196 | D402: 3.7840216 | E402: 35.432021 | F402: 18.955094 | G402: 34.497079 | I402: 63.516274 | J402: 0.17639163 | K402: =AVERAGEIFS(meteorologia!F:F,meteorologia!C:C,valencia!A402) -> 10.19375 | L402: =AVERAGEIFS(meteorologia!G:G,meteorologia!C:C,valencia!A402) -> 60.415 | M402: =LOOKUP(valencia!A:A,Hoja4!A:A,Hoja4!B:B) -> 1 | N402: =LOOKUP(valencia!A:A,Hoja4!A:A,Hoja4!C:C) -> 0
A403: 43502 | B403: 12.909024 | C403: 19.448815 | D403: 3.7699084 | E403: 31.450272 | F403: 18.181126 | G403: 37.024694 | H403: 3.025 | I403: 65.100905 | J403: 0.16697793 | K403: =AVERAGEIFS(meteorologia!F:F,meteorologia!C:C,valencia!A403) -> 10.30625 | L403: =AVERAGEIFS(meteorologia!G:G,meteorologia!C:C,valencia!A403) -> 71.2075 | M403: =LOOKUP(valencia!A:A,Hoja4!A:A,Hoja4!B:B) -> 1 | N403: =LOOKUP(valencia!A:A,Hoja4!A:A,Hoja4!C:C) -> 0
A404: 43503 | B404: 16.365509 | C404: 23.499252 | D404: 3.8690989 | E404: 34.958856 | F404: 21.348936 | G404: 35.281931 | H404: 4.4291667 | I404: 68.113536 | J404: 0.15375 | K404: =AVERAGEIFS(meteorologia!F:F,meteorologia!C:C,valencia!A404) -> 10.86 | L404: =AVERAGEIFS(meteorologia!G:G,meteorologia!C:C,valencia!A404) -> 69.705 | M404: =LOOKUP(valencia!A:A,Hoja4!A:A,Hoja4!B:B) -> 1 | N404: =LOOKUP(valencia!A:A,Hoja4!A:A,Hoja4!C:C) -> 0
A405: 43504 | B405: 22.213699 | C405: 29.047821 | D405: 3.7466044 | E405: 38.834039 | F405: 14.910188 | G405: 34.783641 | H405: 3.4173913 | I405: 57.801624 | J405: 0.152528 | K405: =AVERAGEIFS(meteorologia!F:F,meteorologia!C:C,valencia!A405) -> 9.87 | L405: =AVERAGEIFS(meteorologia!G:G,meteorologia!C:C,valencia!A405) -> 73.0625 | M405: =LOOKUP(valencia!A:A,Hoja4!A:A,Hoja4!B:B) -> 1 | N405: =LOOKUP(valencia!A:A,Hoja4!A:A,Hoja4!C:C) -> 0
A406: 43505 | B406: 22.425 | C406: 26.626506 | D406: 3.6072917 | E406: 43.51095 | F406: 9.1696212 | G406: 28.360871 | H406: 1.65 | I406: 42.504924 | J406: 0.16291667 | K406: =AVERAGEIFS(meteorologia!F:F,meteorologia!C:C,valencia!A406) -> 9.96 | L406: =AVERAGEIFS(meteorologia!G:G,meteorologia!C:C,valencia!A406) -> 68.13125 | M406: =LOOKUP(valencia!A:A,Hoja4!A:A,Hoja4!B:B) -> 1 | N406: =LOOKUP(valencia!A:A,Hoja4!A:A,Hoja4!C:C) -> 0
A407: 43506 | B407: 10.409722 | C407: 15.664853 | D407: 3.5245139 | E407: 54.501717 | F407: 2.8839015 | G407: 12.205663 | H407: 0.625 | I407: 16.572159 | J407: 0.13208333 | K407: =AVERAGEIFS(meteorologia!F:F,meteorologia!C:C,valencia!A407) -> 11.65 | L407: =AVERAGEIFS(meteorologia!G:G,meteorologia!C:C,valencia!A407) -> 62.13875 | M407: =LOOKUP(valencia!A:A,Hoja4!A:A,Hoja4!B:B) -> 1 | N407: =LOOKUP(valencia!A:A,Hoja4!A:A,Hoja4!C:C) -> 0
A408: 43507 | B408: 7.7941819 | C408: 13.733942 | D408: 3.699825 | E408: 50.146742 | F408: 14.963143 | G408: 26.898805 | H408: 2.4363636 | I408: 49.766666 | J408: 0.14628997 | K408: =AVERAGEIFS(meteorologia!F:F,meteorologia!C:C,valencia!A408) -> 11.1775 | L408: =AVERAGEIFS(meteorologia!G:G,meteorologia!C:C,valencia!A408) -> 69.1675 | M408: =LOOKUP(valencia!A:A,Hoja4!A:A,Hoja4!B:B) -> 1 | N408: =LOOKUP(valencia!A:A,Hoja4!A:A,Hoja4!C:C) -> 0
A409: 43508 | B409: 8.6614583 | C409: 14.786699 | D409: 3.5157176 | E409: 46.131431 | F409: 11.935686 | G409: 30.995344 | H409: 1.9583333 | I409: 49.345331 | J409: 0.16742424 | K409: =AVERAGEIFS(meteorologia!F:F,meteorologia!C:C,valencia!A409) -> 7.8825 | L409: =AVERAGEIFS(meteorologia!G:G,meteorologia!C:C,valencia!A409) -> 72.2175 | M409: =LOOKUP(valencia!A:A,Hoja4!A:A,Hoja4!B:B) -> 1 | N409: =LOOKUP(valencia!A:A,Hoja4!A:A,Hoja4!C:C) -> 0
A410: 43509 | B410: 11.959239 | C410: 19.629479 | D410: 3.523636 | E410: 46.433603 | F410: 14.133523 | G410: 30.15181 | H410: 3.7478261 | I410: 51.78647 | J410: 0.16581733 | K410: =AVERAGEIFS(meteorologia!F:F,meteorologia!C:C,valencia!A410) -> 7.49 | L410: =AVERAGEIFS(meteorologia!G:G,meteorologia!C:C,valencia!A410) -> 76.8575 | M410: =LOOKUP(valencia!A:A,Hoja4!A:A,Hoja4!B:B) -> 1 | N410: =LOOKUP(valencia!A:A,Hoja4!A:A,Hoja4!C:C) -> 0
A411: 43510 | B411: 10.978865 | C411: 16.744653 | D411: 3.6192544 | E411: 55.808366 | F411: 9.7473295 | G411: 27.814337 | H411: 3.5041667 | I411: 42.760227 | J411: 0.15083333 | K411: =AVERAGEIFS(meteorologia!F:F,meteorologia!C:C,valencia!A411) -> 8.9375 | L411: =AVERAGEIFS(meteorologia!G:G,meteorologia!C:C,valencia!A411) -> 76.855 | M411: =LOOKUP(valencia!A:A,Hoja4!A:A,Hoja4!B:B) -> 1 | N411: =LOOKUP(valencia!A:A,Hoja4!A:A,Hoja4!C:C) -> 0
A412: 43511 | B412: 18.069444 | C412: 24.847532 | D412: 3.665 | E412: 53.031466 | F412: 7.2091047 | G412: 27.895604 | H412: 2.8291667 | I412: 38.913912 | J412: 0.14666667 | K412: =AVERAGEIFS(meteorologia!F:F,meteorologia!C:C,valencia!A412) -> 8.35625 | L412: =AVERAGEIFS(meteorologia!G:G,meteorologia!C:C,valencia!A412) -> 80.49 | M412: =LOOKUP(valencia!A:A,Hoja4!A:A,Hoja4!B:B) -> 1 | N412: =LOOKUP(valencia!A:A,Hoja4!A:A,Hoja4!C:C) -> 0
A413: 43512 | B413: 20.706845 | C413: 24.852079 | D413: 3.6583958 | E413: 57.486225 | F413: 5.4045346 | G413: 23.219843 | H413: 1.5583333 | I413: 31.508252 | J413: 0.13875 | K413: =AVERAGEIFS(meteorologia!F:F,meteorologia!C:C,valencia!A413) -> 8.26125 | L413: =AVERAGEIFS(meteorologia!G:G,meteorologia!C:C,valencia!A413) -> 77.07375 | M413: =LOOKUP(valencia!A:A,Hoja4!A:A,Hoja4!B:B) -> 1 | N413: =LOOKUP(valencia!A:A,Hoja4!A:A,Hoja4!C:C) -> 1
A414: 43513 | B414: 11.015377 | C414: 14.5622 | D414: 3.1978681 | E414: 64.134943 | F414: 3.0838436 | G414: 16.004746 | H414: 0.9375 | I414: 20.57284 | J414: 0.12375 | K414: =AVERAGEIFS(meteorologia!F:F,meteorologia!C:C,valencia!A414) -> 7.7175 | L414: =AVERAGEIFS(meteorologia!G:G,meteorologia!C:C,valencia!A414) -> 76.5675 | M414: =LOOKUP(valencia!A:A,Hoja4!A:A,Hoja4!B:B) -> 0 | N414: =LOOKUP(valencia!A:A,Hoja4!A:A,Hoja4!C:C) -> 0
... A579: 43678 | B579: 9.9220328 | C579: 16.397308 | D579: 3.2581548 | E579: 66.666908 | F579: 2.8696196 | G579: 9.2665316 | H579: 0.21 | I579: 13.406966 | J579: 0.11025641 | K579: =AVERAGEIFS(meteorologia!F:F,meteorologia!C:C,valencia!A579) -> 24.2125 | L579: =AVERAGEIFS(meteorologia!G:G,meteorologia!C:C,valencia!A579) -> 72.6675 | M579: =LOOKUP(valencia!A:A,Hoja4!A:A,Hoja4!B:B) -> 0 | N579: =LOOKUP(valencia!A:A,Hoja4!A:A,Hoja4!C:C) -> 0
...

Sheet Hoja4
A1: día | B1: ingresos vaslencia | C1: exitus valencia
A2: 40210 | B2: 0 | C2: 0
A3: 42241 | B3: 0 | C3: 0
A4: 42580 | B4: 0 | C4: 0
A5: 42590 | B5: 0 | C5: 0
A6: 42622 | B6: 0 | C6: 0
A7: 42628 | B7: 0 | C7: 0
A8: 42647 | B8: 0 | C8: 0
A9: 42660 | B9: 0 | C9: 0
A10: 42661 | B10: 0 | C10: 0
A11: 42667 | B11: 0 | C11: 0
A12: 42674 | B12: 0 | C12: 0
A13: 42440 | B13: 0 | C13: 0
... A1526: 44195 | B1526: 0 | C1526: 0

Sheet Hoja1
A1: FECHA | B1: PM25 | C1: PM10 | D1: SO2 | E1: O3 | F1: NO | G1: NO2 | H1: C6H6 | I1: NOx | J1: CO | K1: temperatura | L1: humedad | M1: ingresos | N1: exitus
A2: 42741 | B2: =AVERAGE(valencia!B2:B6) -> 14.494784 | C2: =AVERAGE(valencia!C2:C6) -> 17.345876 | D2: =AVERAGE(valencia!D2:D6) -> 3.3031282 | E2: =AVERAGE(valencia!E2:E6) -> 31.293521 | F2: =AVERAGE(valencia!F2:F6) -> 18.93215 | G2: =AVERAGE(valencia!G2:G6) -> 25.380761 | H2: =AVERAGE(valencia!H2:H6) -> 3.1125 | I2: =AVERAGE(valencia!I2:I6) -> 53.723181 | ... L2: =AVERAGE(valencia!L2:L6) -> 79.032857 | M2: 2 | N2: 0
A3: 42742 | B3: =AVERAGE(valencia!B3:B7) -> 13.982663 | C3: =AVERAGE(valencia!C3:C7) -> 16.923149 | D3: =AVERAGE(valencia!D3:D7) -> 3.2745488 | E3: =AVERAGE(valencia!E3:E7) -> 31.078902 | F3: =AVERAGE(valencia!F3:F7) -> 19.493123 | G3: =AVERAGE(valencia!G3:G7) -> 26.023712 | H3: =AVERAGE(valencia!H3:H7) -> 3.1183333 | I3: =AVERAGE(valencia!I3:I7) -> 55.312044 | ... L3: =AVERAGE(valencia!L3:L7) -> 79.432857 | M3: 2 | N3: 0
A4: 42743 | B4: =AVERAGE(valencia!B4:B8) -> 13.665239 | C4: =AVERAGE(valencia!C4:C8) -> 16.634513 | D4: =AVERAGE(valencia!D4:D8) -> 3.2323821 | E4: =AVERAGE(valencia!E4:E8) -> 31.850231 | F4: =AVERAGE(valencia!F4:F8) -> 17.827889 | G4: =AVERAGE(valencia!G4:G8) -> 24.739306 | H4: =AVERAGE(valencia!H4:H8) -> 3.1075 | I4: =AVERAGE(valencia!I4:I8) -> 51.459479 | ... L4: =AVERAGE(valencia!L4:L8) -> 79.83 | M4: 2 | N4: 0
A5: 42744 | B5: =AVERAGE(valencia!B5:B9) -> 12.890239 | C5: =AVERAGE(valencia!C5:C9) -> 15.51419 | D5: =AVERAGE(valencia!D5:D9) -> 3.1537664 | E5: =AVERAGE(valencia!E5:E9) -> 32.906692 | F5: =AVERAGE(valencia!F5:F9) -> 13.615175 | G5: =AVERAGE(valencia!G5:G9) -> 22.659105 | H5: =AVERAGE(valencia!H5:H9) -> 2.7825 | I5: =AVERAGE(valencia!I5:I9) -> 42.93122 | ... L5: =AVERAGE(valencia!L5:L9) -> 81.076 | M5: 2 | N5: 0
A6: 42745 | B6: =AVERAGE(valencia!B6:B10) -> 12.528118 | C6: =AVERAGE(valencia!C6:C10) -> 15.079108 | D6: =AVERAGE(valencia!D6:D10) -> 3.1342395 | E6: =AVERAGE(valencia!E6:E10) -> 33.161259 | F6: =AVERAGE(valencia!F6:F10) -> 12.313852 | G6: =AVERAGE(valencia!G6:G10) -> 22.71357 | H6: =AVERAGE(valencia!H6:H10) -> 2.7341667 | I6: =AVERAGE(valencia!I6:I10) -> 41.028445 | ... L6: =AVERAGE(valencia!L6:L10) -> 81.902 | M6: 2 | N6: 0
A7: 42746 | B7: =AVERAGE(valencia!B7:B11) -> 12.113408 | C7: =AVERAGE(valencia!C7:C11) -> 14.858906 | D7: =AVERAGE(valencia!D7:D11) -> 3.0590812 | E7: =AVERAGE(valencia!E7:E11) -> 34.658778 | F7: =AVERAGE(valencia!F7:F11) -> 11.385056 | G7: =AVERAGE(valencia!G7:G11) -> 21.182079 | H7: =AVERAGE(valencia!H7:H11) -> 2.5791667 | I7: =AVERAGE(valencia!I7:I11) -> 38.030239 | ... L7: =AVERAGE(valencia!L7:L11) -> 80.680571 | M7: 2 | N7: 0
A8: 42747 | B8: =AVERAGE(valencia!B8:B12) -> 10.848191 | C8: =AVERAGE(valencia!C8:C12) -> 14.013847 | D8: =AVERAGE(valencia!D8:D12) -> 3.1164383 | E8: =AVERAGE(valencia!E8:E12) -> 36.701213 | F8: =AVERAGE(valencia!F8:F12) -> 13.009958 | G8: =AVERAGE(valencia!G8:G12) -> 22.30998 | H8: =AVERAGE(valencia!H8:H12) -> 2.6525 | I8: =AVERAGE(valencia!I8:I12) -> 41.592689 | ... L8: =AVERAGE(valencia!L8:L12) -> 77.272857 | M8: 2 | N8: 0
A9: 42748 | B9: =AVERAGE(valencia!B9:B13) -> 9.2186453 | C9: =AVERAGE(valencia!C9:C13) -> 12.750211 | D9: =AVERAGE(valencia!D9:D13) -> 3.1663867 | E9: =AVERAGE(valencia!E9:E13) -> 36.601552 | F9: =AVERAGE(valencia!F9:F13) -> 14.088537 | G9: =AVERAGE(valencia!G9:G13) -> 22.197769 | H9: =AVERAGE(valencia!H9:H13) -> 2.6108333 | I9: =AVERAGE(valencia!I9:I13) -> 43.02445 | ... L9: =AVERAGE(valencia!L9:L13) -> 73.965714 | M9: 2 | N9: 0
A10: 42749 | B10: =AVERAGE(valencia!B10:B14) -> 7.2972816 | C10: =AVERAGE(valencia!C10:C14) -> 10.947483 | D10: =AVERAGE(valencia!D10:D14) -> 3.1423589 | E10: =AVERAGE(valencia!E10:E14) -> 42.308077 | F10: =AVERAGE(valencia!F10:F14) -> 13.04861 | G10: =AVERAGE(valencia!G10:G14) -> 20.558784 | H10: =AVERAGE(valencia!H10:H14) -> 2.3508333 | I10: =AVERAGE(valencia!I10:I14) -> 39.74619 | ... L10: =AVERAGE(valencia!L10:L14) -> 68.176 | M10: 2 | N10: 0
A11: 42750 | B11: =AVERAGE(valencia!B11:B15) -> 4.7609821 | C11: =AVERAGE(valencia!C11:C15) -> 8.1473144 | D11: =AVERAGE(valencia!D11:D15) -> 3.0807558 | E11: =AVERAGE(valencia!E11:E15) -> 50.122428 | F11: =AVERAGE(valencia!F11:F15) -> 10.093613 | G11: =AVERAGE(valencia!G11:G15) -> 16.07208 | H11: =AVERAGE(valencia!H11:H15) -> 1.9158333 | I11: =AVERAGE(valencia!I11:I15) -> 30.669486 | ... L11: =AVERAGE(valencia!L11:L15) -> 61.389143 | M11: 2 | N11: 0
A12: 42751 | B12: =AVERAGE(valencia!B12:B16) -> 3.7141765 | C12: =AVERAGE(valencia!C12:C16) -> 6.6225922 | D12: =AVERAGE(valencia!D12:D16) -> 3.0872024 | E12: =AVERAGE(valencia!E12:E16) -> 55.457831 | F12: =AVERAGE(valencia!F12:F16) -> 8.7992381 | G12: =AVERAGE(valencia!G12:G16) -> 13.646261 | H12: =AVERAGE(valencia!H12:H16) -> 1.6983333 | I12: =AVERAGE(valencia!I12:I16) -> 26.244614 | ... L12: =AVERAGE(valencia!L12:L16) -> 57.934857 | M12: 2 | N12: 0
A13: 42752 | B13: =AVERAGE(valencia!B13:B17) -> 3.1460606 | C13: =AVERAGE(valencia!C13:C17) -> 6.1767424 | D13: =AVERAGE(valencia!D13:D17) -> 3.0712581 | E13: =AVERAGE(valencia!E13:E17) -> 59.217201 | F13: =AVERAGE(valencia!F13:F17) -> 6.5904765 | G13: =AVERAGE(valencia!G13:G17) -> 10.656099 | H13: =AVERAGE(valencia!H13:H17) -> 1.4433333 | I13: =AVERAGE(valencia!I13:I17) -> 19.828707 | ... L13: =AVERAGE(valencia!L13:L17) -> 54.235143 | M13: 2 | N13: 0
... A361: 43100 | B361: =AVERAGE(valencia!B361:B365) -> 5.4074852 | C361: =AVERAGE(valencia!C361:C365) -> 12.293053 | D361: =AVERAGE(valencia!D361:D365) -> 3.2004045 | E361: =AVERAGE(valencia!E361:E365) -> 52.550713 | F361: =AVERAGE(valencia!F361:F365) -> 5.0882569 | G361: =AVERAGE(valencia!G361:G365) -> 12.36581 | H361: =AVERAGE(valencia!H361:H365) -> 1.2096212 | I361: =AVERAGE(valencia!I361:I365) -> 19.726458 | ... L361: =AVERAGE(valencia!L361:L365) -> 59.88575 | M361: 2 | N361: 1
A362: 43471 | B362: =AVERAGE(valencia!B367:B371) -> 13.590064 | C362: =AVERAGE(valencia!C367:C371) -> 19.102958 | D362: =AVERAGE(valencia!D367:D371) -> 3.7023057 | E362: =AVERAGE(valencia!E367:E371) -> 29.760319 | F362: =AVERAGE(valencia!F367:F371) -> 14.533463 | G362: =AVERAGE(valencia!G367:G371) -> 27.696751 | H362: =AVERAGE(valencia!H367:H371) -> 1.6262681 | I362: =AVERAGE(valencia!I367:I371) -> 49.509347 | ... L362: =AVERAGE(valencia!L367:L371) -> 74.771107 | M362: 2 | N362: 0
A363: 43472 | B363: =AVERAGE(valencia!B368:B372) -> 14.193056 | C363: =AVERAGE(valencia!C368:C372) -> 20.159316 | D363: =AVERAGE(valencia!D368:D372) -> 3.7910057 | E363: =AVERAGE(valencia!E368:E372) -> 29.712776 | F363: =AVERAGE(valencia!F368:F372) -> 15.22161 | G363: =AVERAGE(valencia!G368:G372) -> 28.331734 | H363: =AVERAGE(valencia!H368:H372) -> 1.6654348 | I363: =AVERAGE(valencia!I368:I372) -> 51.073474 | ... L363: =AVERAGE(valencia!L368:L372) -> 72.849107 | M363: 2 | N363: 0
A364: 43473 | B364: =AVERAGE(valencia!B369:B373) -> 14.378283 | C364: =AVERAGE(valencia!C369:C373) -> 20.872472 | D364: =AVERAGE(valencia!D369:D373) -> 3.8785227 | E364: =AVERAGE(valencia!E369:E373) -> 30.619029 | F364: =AVERAGE(valencia!F369:F373) -> 16.803253 | G364: =AVERAGE(valencia!G369:G373) -> 28.724598 | H364: =AVERAGE(valencia!H369:H373) -> 1.8104348 | I364: =AVERAGE(valencia!I369:I373) -> 53.799708 | ... L364: =AVERAGE(valencia!L369:L373) -> 73.239107 | M364: 2 | N364: 0
A365: 43474 | B365: =AVERAGE(valencia!B370:B374) -> 14.971338 | C365: =AVERAGE(valencia!C370:C374) -> 21.901297 | D365: =AVERAGE(valencia!D370:D374) -> 3.8963864 | E365: =AVERAGE(valencia!E370:E374) -> 31.270946 | F365: =AVERAGE(valencia!F370:F374) -> 16.787756 | G365: =AVERAGE(valencia!G370:G374) -> 28.835977 | H365: =AVERAGE(valencia!H370:H374) -> 1.8079348 | I365: =AVERAGE(valencia!I370:I374) -> 53.890244 | ... L365: =AVERAGE(valencia!L370:L374) -> 71.583107 | M365: 2 | N365: 0
A366: 43475 | B366: =AVERAGE(valencia!B371:B375) -> 14.024597 | C366: =AVERAGE(valencia!C371:C375) -> 21.719134 | D366: =AVERAGE(valencia!D371:D375) -> 3.9539641 | E366: =AVERAGE(valencia!E371:E375) -> 34.553279 | F366: =AVERAGE(valencia!F371:F375) -> 17.369799 | G366: =AVERAGE(valencia!G371:G375) -> 27.773714 | H366: =AVERAGE(valencia!H371:H375) -> 1.7083333 | I366: =AVERAGE(valencia!I371:I375) -> 53.677322 | ... L366: =AVERAGE(valencia!L371:L375) -> 66.470357 | M366: 2 | N366: 0
A367: 43476 | B367: =AVERAGE(valencia!B372:B376) -> 11.765948 | C367: =AVERAGE(valencia!C372:C376) -> 19.999067 | D367: =AVERAGE(valencia!D372:D376) -> 3.9255039 | E367: =AVERAGE(valencia!E372:E376) -> 39.300652 | F367: =AVERAGE(valencia!F372:F376) -> 16.925076 | G367: =AVERAGE(valencia!G372:G376) -> 27.382858 | H367: =AVERAGE(valencia!H372:H376) -> 1.6383333 | I367: =AVERAGE(valencia!I372:I376) -> 52.687875 | ... L367: =AVERAGE(valencia!L372:L376) -> 62.57025 | M367: 2 | N367: 0
A368: 43477 | B368: =AVERAGE(valencia!B373:B377) -> 11.222135 | C368: =AVERAGE(valencia!C373:C377) -> 20.976911 | D368: =AVERAGE(valencia!D373:D377) -> 4.038468 | E368: =AVERAGE(valencia!E373:E377) -> 41.218592 | F368: =AVERAGE(valencia!F373:F377) -> 19.112872 | G368: =AVERAGE(valencia!G373:G377) -> 28.844742 | H368: =AVERAGE(valencia!H373:H377) -> 1.6841667 | I368: =AVERAGE(valencia!I373:I377) -> 57.613666 | ... L368: =AVERAGE(valencia!L373:L377) -> 61.38725 | M368: 2 | N368: 0
A369: 43478 | B369: =AVERAGE(valencia!B374:B378) -> 11.266011 | C369: =AVERAGE(valencia!C374:C378) -> 20.541248 | D369: =AVERAGE(valencia!D374:D378) -> 3.8878488 | E369: =AVERAGE(valencia!E374:E378) -> 42.82602 | F369: =AVERAGE(valencia!F374:F378) -> 16.313879 | G369: =AVERAGE(valencia!G374:G378) -> 28.279306 | H369: =AVERAGE(valencia!H374:H378) -> 1.53 | I369: =AVERAGE(valencia!I374:I378) -> 52.821993 | ... L369: =AVERAGE(valencia!L374:L378) -> 59.221 | M369: 2 | N369: 0
A370: 43479 | B370: =AVERAGE(valencia!B375:B379) -> 9.8987762 | C370: =AVERAGE(valencia!C375:C379) -> 18.280491 | D370: =AVERAGE(valencia!D375:D379) -> 3.8744638 | E370: =AVERAGE(valencia!E375:E379) -> 44.622503 | F370: =AVERAGE(valencia!F375:F379) -> 14.378044 | G370: =AVERAGE(valencia!G375:G379) -> 26.440845 | H370: =AVERAGE(valencia!H375:H379) -> 1.4395833 | I370: =AVERAGE(valencia!I375:I379) -> 48.002343 | ... L370: =AVERAGE(valencia!L375:L379) -> 57.9715 | M370: 2 | N370: 0
A371: 43480 | B371: =AVERAGE(valencia!B376:B380) -> 9.4992424 | C371: =AVERAGE(valencia!C376:C380) -> 17.664378 | D371: =AVERAGE(valencia!D376:D380) -> 3.9280395 | E371: =AVERAGE(valencia!E376:E380) -> 42.575875 | F371: =AVERAGE(valencia!F376:F380) -> 15.493141 | G371: =AVERAGE(valencia!G376:G380) -> 28.240111 | H371: =AVERAGE(valencia!H376:H380) -> 1.5347222 | I371: =AVERAGE(valencia!I376:I380) -> 51.3308 | ... L371: =AVERAGE(valencia!L376:L380) -> 59.8695 | M371: 2 | N371: 0
A372: 43481 | B372: =AVERAGE(valencia!B377:B381) -> 11.015909 | C372: =AVERAGE(valencia!C377:C381) -> 19.178201 | D372: =AVERAGE(valencia!D377:D381) -> 4.1518689 | E372: =AVERAGE(valencia!E377:E381) -> 37.425358 | F372: =AVERAGE(valencia!F377:F381) -> 19.306464 | G372: =AVERAGE(valencia!G377:G381) -> 30.856847 | H372: =AVERAGE(valencia!H377:H381) -> 1.8395833 | I372: =AVERAGE(valencia!I377:I381) -> 59.726804 | ... L372: =AVERAGE(valencia!L377:L381) -> 65.4665 | M372: 2 | N372: 0
A373: 43482 | B373: =AVERAGE(valencia!B378:B382) -> 14.115909 | C373: =AVERAGE(valencia!C378:C382) -> 21.180757 | D373: =AVERAGE(valencia!D378:D382) -> 4.0456468 | E373: =AVERAGE(valencia!E378:E382) -> 34.239361 | F373: =AVERAGE(valencia!F378:F382) -> 19.827786 | G373: =AVERAGE(valencia!G378:G382) -> 31.476584 | H373: =AVERAGE(valencia!H378:H382) -> 1.8 | I373: =AVERAGE(valencia!I378:I382) -> 61.16011 | ... L373: =AVERAGE(valencia!L378:L382) -> 70.4845 | M373: 2 | N373: 0
... A721: 43830 | B721: =AVERAGE(valencia!B726:B730) -> 18.000107 | C721: =AVERAGE(valencia!C726:C730) -> 21.427802 | D721: =AVERAGE(valencia!D726:D730) -> 3.9171088 | E721: =AVERAGE(valencia!E726:E730) -> 27.974717 | F721: =AVERAGE(valencia!F726:F730) -> 13.109768 | G721: =AVERAGE(valencia!G726:G730) -> 21.142343 | H721: =AVERAGE(valencia!H726:H730) -> 4.1446377 | I721: =AVERAGE(valencia!I726:I730) -> 41.218564 | ... L721: =AVERAGE(valencia!L726:L730) -> 81.86375 | M721: 0 | N721: 0
